2023-09-16 11:16:59,043 - pyswarms.backend.generators - ERROR - Bounds and/or init_pos should be of size (3,)
Traceback (most recent call last):
  File "G:\anaconda3\envs\py38\lib\site-packages\pyswarms\backend\generators.py", line 74, in generate_swarm
    lb, ub = bounds
ValueError: too many values to unpack (expected 2)
2023-09-16 11:21:36,626 - pyswarms.backend.generators - ERROR - Bounds and/or init_pos should be of size (3,)
Traceback (most recent call last):
  File "G:\anaconda3\envs\py38\lib\site-packages\pyswarms\backend\generators.py", line 74, in generate_swarm
    lb, ub = bounds
ValueError: too many values to unpack (expected 2)
2023-09-16 11:22:46,120 - pyswarms.backend.generators - ERROR - Bounds and/or init_pos should be of size (3,)
Traceback (most recent call last):
  File "G:\anaconda3\envs\py38\lib\site-packages\pyswarms\backend\generators.py", line 74, in generate_swarm
    lb, ub = bounds
ValueError: too many values to unpack (expected 2)
2023-09-16 11:24:05,631 - pyswarms.backend.generators - ERROR - Bounds and/or init_pos should be of size (3,)
Traceback (most recent call last):
  File "G:\anaconda3\envs\py38\lib\site-packages\pyswarms\backend\generators.py", line 74, in generate_swarm
    lb, ub = bounds
ValueError: too many values to unpack (expected 2)
